Workbook

Sheet V-n SL
A1: CESSNA CITATION XLS+ | B1: MIDTERM 2
B4: =2.20462*B5 -> 20198.728 | D4: MANEUVER | M4: GUST
A5: Masa (kg) | B5: 9162 | D5: V eq. m/s | E5: V eq. KEAS | F5: Mach (Ve/Cse) | G5: q dynamic pressure (lb/ft^2) | H5: Clmax_m/Clmax_0 | I5: Cl max_m | J5: Cl max_m (-) | K5: positive load factor n | L5: negative load factor | M5: Cl alpha_m/cl alpha 0 | N5: Cl alpha_m | O5: μ | P5: Kg | Q5: positive gust load factor VB | R5: negative gust load factor VB | S5: positive gust load factor Vc | T5: negative gust load factor Vc | U5: positive gust load factor Vd | V5: negative gust load factor Vd | X5: positive load factor with flaps extended
A6: h (ft) | B6: 0 | D6: 0 | E6: =1.94384*D6 -> 0 | F6: =E6/$B$9 -> 0 | G6: =(0.5*$B$26*D6^2)*0.020885434273039 -> 0 | H6: 1 | I6: =H6*$B$10 -> 2.2 | J6: =$B$28*$H$6 -> -1.1 | K6: =((G6/0.020885434273039)*I6*$B$13)/($B$5*$B$11) -> 0 | L6: =((G6/0.020885434273039)*J6*$B$13)/($B$5*$B$11) -> 0 | O6: =2*$B$5/($B$26*$B$27*$B$25*$B$13) -> 39.37849 | P6: =(0.88*O6)/(5.3+O6) -> 0.77560972 | Q6: Does not apply | R6: Does not apply | S6: =1+($P$6*56*0.3048*D6*$B$26*$B$25*$B$13)/(2*$B$5*$B$11) -> 1 | T6: =1-($P$6*56*0.3048*D6*$B$26*$B$25*$B$13)/(2*$B$5*$B$11) -> 1 | U6: =1+($P$6*28*0.3048*D6*$B$26*$B$25*$B$13)/(2*$B$5*$B$11) -> 1 | V6: =1-($P$6*28*0.3048*D6*$B$26*$B$25*$B$13)/(2*$B$5*$B$11) -> 1 | X6: =((G6/0.020885434273039)*I6*1.15*$B$13)/($B$5*$B$11) -> 0
A7: Vc KEAS | B7: =441 -> 441 | D7: 10.29 | E7: =1.94384*D7 -> 20.002114 | F7: =E7/$B$9 -> 0.030238425 | G7: =(0.5*$B$26*D7^2)*0.020885434273039 -> 1.3545042 | H7: 1 | I7: =H7*$B$10 -> 2.2 | J7: =$B$28*$H$6 -> -1.1 | K7: =((G7/0.020885434273039)*I7*$B$13)/($B$5*$B$11) -> 0.054528929 | L7: =((G7/0.020885434273039)*J7*$B$13)/($B$5*$B$11) -> -0.027264465 | O7: =2*$B$5/($B$26*$B$27*$B$25*$B$13) -> 39.37849 | P7: =(0.88*O7)/(5.3+O7) -> 0.77560972 | S7: =1+($P$6*56*0.3048*D7*$B$26*$B$25*$B$13)/(2*$B$5*$B$11) -> 1.1668125 | T7: =1-($P$6*56*0.3048*D7*$B$26*$B$25*$B$13)/(2*$B$5*$B$11) -> 0.83318751 | U7: =1+($P$6*28*0.3048*D7*$B$26*$B$25*$B$13)/(2*$B$5*$B$11) -> 1.0834062 | V7: =1-($P$6*28*0.3048*D7*$B$26*$B$25*$B$13)/(2*$B$5*$B$11) -> 0.91659376 | X7: =((G7/0.020885434273039)*I7*1.15*$B$13)/($B$5*$B$11) -> 0.062708269
A8: Vd KEAS | B8: =1.25*B7 -> 551.25 | D8: 20 | E8: =1.94384*D8 -> 38.8768 | F8: =E8/$B$9 -> 0.05877245 | G8: =(0.5*$B$26*D8^2)*0.020885434273039 -> 5.1169314 | H8: 1 | I8: =H8*$B$10 -> 2.2 | J8: =$B$28*$H$6 -> -1.1 | K8: =((G8/0.020885434273039)*I8*$B$13)/($B$5*$B$11) -> 0.20599478 | L8: =((G8/0.020885434273039)*J8*$B$13)/($B$5*$B$11) -> -0.10299739 | O8: =2*$B$5/($B$26*$B$27*$B$25*$B$13) -> 39.37849 | P8: =(0.88*O8)/(5.3+O8) -> 0.77560972 | S8: =1+($P$6*56*0.3048*D8*$B$26*$B$25*$B$13)/(2*$B$5*$B$11) -> 1.3242225 | T8: =1-($P$6*56*0.3048*D8*$B$26*$B$25*$B$13)/(2*$B$5*$B$11) -> 0.67577748 | U8: =1+($P$6*28*0.3048*D8*$B$26*$B$25*$B$13)/(2*$B$5*$B$11) -> 1.1621113 | V8: =1-($P$6*28*0.3048*D8*$B$26*$B$25*$B$13)/(2*$B$5*$B$11) -> 0.83788874 | X8: =((G8/0.020885434273039)*I8*1.15*$B$13)/($B$5*$B$11) -> 0.236894
A9: Cse KEAS (h ft) | B9: 661.48 | D9: 30 | E9: =1.94384*D9 -> 58.3152 | F9: =E9/$B$9 -> 0.088158674 | G9: =(0.5*$B$26*D9^2)*0.020885434273039 -> 11.513096 | H9: 1 | I9: =H9*$B$10 -> 2.2 | J9: =$B$28*$H$6 -> -1.1 | K9: =((G9/0.020885434273039)*I9*$B$13)/($B$5*$B$11) -> 0.46348825 | L9: =((G9/0.020885434273039)*J9*$B$13)/($B$5*$B$11) -> -0.23174413 | O9: =2*$B$5/($B$26*$B$27*$B$25*$B$13) -> 39.37849 | P9: =(0.88*O9)/(5.3+O9) -> 0.77560972 | S9: =1+($P$6*56*0.3048*D9*$B$26*$B$25*$B$13)/(2*$B$5*$B$11) -> 1.4863338 | T9: =1-($P$6*56*0.3048*D9*$B$26*$B$25*$B$13)/(2*$B$5*$B$11) -> 0.51366622 | U9: =1+($P$6*28*0.3048*D9*$B$26*$B$25*$B$13)/(2*$B$5*$B$11) -> 1.2431669 | V9: =1-($P$6*28*0.3048*D9*$B$26*$B$25*$B$13)/(2*$B$5*$B$11) -> 0.75683311 | X9: =((G9/0.020885434273039)*I9*1.15*$B$13)/($B$5*$B$11) -> 0.53301149
A10: (Clmax)0 at M=0 | B10: 2.2 | D10: 40 | E10: =1.94384*D10 -> 77.7536 | F10: =E10/$B$9 -> 0.1175449 | G10: =(0.5*$B$26*D10^2)*0.020885434273039 -> 20.467726 | H10: 1 | I10: =H10*$B$10 -> 2.2 | J10: =$B$28*$H$6 -> -1.1 | K10: =((G10/0.020885434273039)*I10*$B$13)/($B$5*$B$11) -> 0.82397911 | L10: =((G10/0.020885434273039)*J10*$B$13)/($B$5*$B$11) -> -0.41198956 | O10: =2*$B$5/($B$26*$B$27*$B$25*$B$13) -> 39.37849 | P10: =(0.88*O10)/(5.3+O10) -> 0.77560972 | S10: =1+($P$6*56*0.3048*D10*$B$26*$B$25*$B$13)/(2*$B$5*$B$11) -> 1.648445 | T10: =1-($P$6*56*0.3048*D10*$B$26*$B$25*$B$13)/(2*$B$5*$B$11) -> 0.35155496 | U10: =1+($P$6*28*0.3048*D10*$B$26*$B$25*$B$13)/(2*$B$5*$B$11) -> 1.3242225 | V10: =1-($P$6*28*0.3048*D10*$B$26*$B$25*$B$13)/(2*$B$5*$B$11) -> 0.67577748 | X10: =((G10/0.020885434273039)*I10*1.15*$B$13)/($B$5*$B$11) -> 0.94757598
A11: Gravity m/s^2 | B11: 9.81 | D11: 44.065946 | E11: =1.94384*D11 -> 85.657149 | F11: =E11/$B$9 -> 0.12949318 | G11: =(0.5*$B$26*D11^2)*0.020885434273039 -> 24.840241 | H11: 1 | I11: =H11*$B$10 -> 2.2 | J11: =$B$28*$H$6 -> -1.1 | K11: =((G11/0.020885434273039)*I11*$B$13)/($B$5*$B$11) -> 1.0000056 | L11: =((G11/0.020885434273039)*J11*$B$13)/($B$5*$B$11) -> -0.50000279 | O11: =2*$B$5/($B$26*$B$27*$B$25*$B$13) -> 39.37849 | P11: =(0.88*O11)/(5.3+O11) -> 0.77560972 | S11: =1+($P$6*56*0.3048*D11*$B$26*$B$25*$B$13)/(2*$B$5*$B$11) -> 1.7143586 | T11: =1-($P$6*56*0.3048*D11*$B$26*$B$25*$B$13)/(2*$B$5*$B$11) -> 0.28564139 | U11: =1+($P$6*28*0.3048*D11*$B$26*$B$25*$B$13)/(2*$B$5*$B$11) -> 1.3571793 | V11: =1-($P$6*28*0.3048*D11*$B$26*$B$25*$B$13)/(2*$B$5*$B$11) -> 0.64282069 | X11: =((G11/0.020885434273039)*I11*1.15*$B$13)/($B$5*$B$11) -> 1.1500064
A12: span b (m) | B12: 16.97 | D12: 58.115916 | E12: =1.94384*D12 -> 112.96804 | F12: =E12/$B$9 -> 0.17078074 | G12: =(0.5*$B$26*D12^2)*0.020885434273039 -> 43.205575 | H12: 1 | I12: =H12*$B$10 -> 2.2 | J12: =$B$28*$H$6 -> -1.1 | K12: =((G12/0.020885434273039)*I12*$B$13)/($B$5*$B$11) -> 1.7393477 | L12: =((G12/0.020885434273039)*J12*$B$13)/($B$5*$B$11) -> -0.86967384 | O12: =2*$B$5/($B$26*$B$27*$B$25*$B$13) -> 39.37849 | P12: =(0.88*O12)/(5.3+O12) -> 0.77560972 | S12: =1+($P$6*56*0.3048*D12*$B$26*$B$25*$B$13)/(2*$B$5*$B$11) -> 1.9421244 | T12: =1-($P$6*56*0.3048*D12*$B$26*$B$25*$B$13)/(2*$B$5*$B$11) -> 0.057875551 | U12: =1+($P$6*28*0.3048*D12*$B$26*$B$25*$B$13)/(2*$B$5*$B$11) -> 1.4710622 | V12: =1-($P$6*28*0.3048*D12*$B$26*$B$25*$B$13)/(2*$B$5*$B$11) -> 0.52893778 | X12: =((G12/0.020885434273039)*I12*1.15*$B$13)/($B$5*$B$11) -> 2.0002498
A13: wing area S (m^2) | B13: 34.35 | D13: 62.338847 | E13: =1.94384*D13 -> 121.17674 | F13: =E13/$B$9 -> 0.18319034 | G13: =(0.5*$B$26*D13^2)*0.020885434273039 -> 49.712675 | H13: 1 | I13: =H13*$B$10 -> 2.2 | J13: =$B$28*$H$6 -> -1.1 | K13: =((G13/0.020885434273039)*I13*$B$13)/($B$5*$B$11) -> 2.0013071 | L13: =((G13/0.020885434273039)*J13*$B$13)/($B$5*$B$11) -> -1.0006536 | O13: =2*$B$5/($B$26*$B$27*$B$25*$B$13) -> 39.37849 | P13: =(0.88*O13)/(5.3+O13) -> 0.77560972 | S13: =1+($P$6*56*0.3048*D13*$B$26*$B$25*$B$13)/(2*$B$5*$B$11) -> 2.0105829 | T13: =1-($P$6*56*0.3048*D13*$B$26*$B$25*$B$13)/(2*$B$5*$B$11) -> -0.010582902 | U13: =1+($P$6*28*0.3048*D13*$B$26*$B$25*$B$13)/(2*$B$5*$B$11) -> 1.5052915 | V13: =1-($P$6*28*0.3048*D13*$B$26*$B$25*$B$13)/(2*$B$5*$B$11) -> 0.49470855
A14: Wing load W/S (kg/m^2) | B14: =B5/B13 -> 266.72489 | D14: 74.912593 | E14: =1.94384*D14 -> 145.6181 | F14: =E14/$B$9 -> 0.22013983 | G14: =(0.5*$B$26*D14^2)*0.020885434273039 -> 71.789225 | H14: 1 | I14: =H14*$B$10 -> 2.2 | J14: =$B$28*$H$6 -> -1.1 | K14: =((G14/0.020885434273039)*I14*$B$13)/($B$5*$B$11) -> 2.8900535 | L14: =((G14/0.020885434273039)*J14*$B$13)/($B$5*$B$11) -> -1.4450268 | O14: =2*$B$5/($B$26*$B$27*$B$25*$B$13) -> 39.37849 | P14: =(0.88*O14)/(5.3+O14) -> 0.77560972 | S14: =1+($P$6*56*0.3048*D14*$B$26*$B$25*$B$13)/(2*$B$5*$B$11) -> 2.2144175 | T14: =1-($P$6*56*0.3048*D14*$B$26*$B$25*$B$13)/(2*$B$5*$B$11) -> -0.21441749 | U14: =1+($P$6*28*0.3048*D14*$B$26*$B$25*$B$13)/(2*$B$5*$B$11) -> 1.6072087 | V14: =1-($P$6*28*0.3048*D14*$B$26*$B$25*$B$13)/(2*$B$5*$B$11) -> 0.39279125
A15: positive load factor n1 | B15: =2.1+(24000/(B4+10000)) -> 2.8947354 | D15: 90 | E15: =1.94384*D15 -> 174.9456 | F15: =E15/$B$9 -> 0.26447602 | G15: =(0.5*$B$26*D15^2)*0.020885434273039 -> 103.61786 | H15: 1 | I15: =H15*$B$10 -> 2.2 | J15: =$B$28*$H$6 -> -1.1 | K15: =((G15/0.020885434273039)*I15*$B$13)/($B$5*$B$11) -> 4.1713943 | L15: =((G15/0.020885434273039)*J15*$B$13)/($B$5*$B$11) -> -2.0856971 | O15: =2*$B$5/($B$26*$B$27*$B$25*$B$13) -> 39.37849 | P15: =(0.88*O15)/(5.3+O15) -> 0.77560972 | S15: =1+($P$6*56*0.3048*D15*$B$26*$B$25*$B$13)/(2*$B$5*$B$11) -> 2.4590013 | T15: =1-($P$6*56*0.3048*D15*$B$26*$B$25*$B$13)/(2*$B$5*$B$11) -> -0.45900135 | U15: =1+($P$6*28*0.3048*D15*$B$26*$B$25*$B$13)/(2*$B$5*$B$11) -> 1.7295007 | V15: =1-($P$6*28*0.3048*D15*$B$26*$B$25*$B$13)/(2*$B$5*$B$11) -> 0.27049933
A16: negative limit load factor | B16: -1 | D16: 100 | E16: =1.94384*D16 -> 194.384 | F16: =E16/$B$9 -> 0.29386225 | G16: =(0.5*$B$26*D16^2)*0.020885434273039 -> 127.92328 | H16: 1 | I16: =H16*$B$10 -> 2.2 | J16: =$B$28*$H$6 -> -1.1 | K16: =((G16/0.020885434273039)*I16*$B$13)/($B$5*$B$11) -> 5.1498695 | L16: =((G16/0.020885434273039)*J16*$B$13)/($B$5*$B$11) -> -2.5749347 | O16: =2*$B$5/($B$26*$B$27*$B$25*$B$13) -> 39.37849 | P16: =(0.88*O16)/(5.3+O16) -> 0.77560972 | S16: =1+($P$6*56*0.3048*D16*$B$26*$B$25*$B$13)/(2*$B$5*$B$11) -> 2.6211126 | T16: =1-($P$6*56*0.3048*D16*$B$26*$B$25*$B$13)/(2*$B$5*$B$11) -> -0.62111261 | U16: =1+($P$6*28*0.3048*D16*$B$26*$B$25*$B$13)/(2*$B$5*$B$11) -> 1.8105563 | V16: =1-($P$6*28*0.3048*D16*$B$26*$B$25*$B$13)/(2*$B$5*$B$11) -> 0.1894437
A17: Aspect ratio | B17: 8.4 | D17: 110 | E17: =1.94384*D17 -> 213.8224 | F17: =E17/$B$9 -> 0.32324847 | G17: =(0.5*$B$26*D17^2)*0.020885434273039 -> 154.78717 | H17: 1 | I17: =H17*$B$10 -> 2.2 | J17: =$B$28*$H$6 -> -1.1 | K17: =((G17/0.020885434273039)*I17*$B$13)/($B$5*$B$11) -> 6.231342 | L17: =((G17/0.020885434273039)*J17*$B$13)/($B$5*$B$11) -> -3.115671 | O17: =2*$B$5/($B$26*$B$27*$B$25*$B$13) -> 39.37849 | P17: =(0.88*O17)/(5.3+O17) -> 0.77560972 | S17: =1+($P$6*56*0.3048*D17*$B$26*$B$25*$B$13)/(2*$B$5*$B$11) -> 2.7832239 | T17: =1-($P$6*56*0.3048*D17*$B$26*$B$25*$B$13)/(2*$B$5*$B$11) -> -0.78322387 | U17: =1+($P$6*28*0.3048*D17*$B$26*$B$25*$B$13)/(2*$B$5*$B$11) -> 1.8916119 | V17: =1-($P$6*28*0.3048*D17*$B$26*$B$25*$B$13)/(2*$B$5*$B$11) -> 0.10838807
A18: Taper ratio (lambda) | B18: 0.2 | D18: 120 | E18: =1.94384*D18 -> 233.2608 | F18: =E18/$B$9 -> 0.3526347 | G18: =(0.5*$B$26*D18^2)*0.020885434273039 -> 184.20953 | H18: 1 | I18: =H18*$B$10 -> 2.2 | J18: =$B$28*$H$6 -> -1.1 | K18: =((G18/0.020885434273039)*I18*$B$13)/($B$5*$B$11) -> 7.415812 | L18: =((G18/0.020885434273039)*J18*$B$13)/($B$5*$B$11) -> -3.707906 | O18: =2*$B$5/($B$26*$B$27*$B$25*$B$13) -> 39.37849 | P18: =(0.88*O18)/(5.3+O18) -> 0.77560972 | S18: =1+($P$6*56*0.3048*D18*$B$26*$B$25*$B$13)/(2*$B$5*$B$11) -> 2.9453351 | T18: =1-($P$6*56*0.3048*D18*$B$26*$B$25*$B$13)/(2*$B$5*$B$11) -> -0.94533513 | U18: =1+($P$6*28*0.3048*D18*$B$26*$B$25*$B$13)/(2*$B$5*$B$11) -> 1.9726676 | V18: =1-($P$6*28*0.3048*D18*$B$26*$B$25*$B$13)/(2*$B$5*$B$11) -> 0.027332435
A19: aflechamiento (Swept)Λ | B19: 0 | D19: 130 | E19: =1.94384*D19 -> 252.6992 | F19: =E19/$B$9 -> 0.38202092 | G19: =(0.5*$B$26*D19^2)*0.020885434273039 -> 216.19035 | H19: 1 | I19: =H19*$B$10 -> 2.2 | J19: =$B$28*$H$6 -> -1.1 | K19: =((G19/0.020885434273039)*I19*$B$13)/($B$5*$B$11) -> 8.7032794 | L19: =((G19/0.020885434273039)*J19*$B$13)/($B$5*$B$11) -> -4.3516397 | O19: =2*$B$5/($B$26*$B$27*$B$25*$B$13) -> 39.37849 | P19: =(0.88*O19)/(5.3+O19) -> 0.77560972 | S19: =1+($P$6*56*0.3048*D19*$B$26*$B$25*$B$13)/(2*$B$5*$B$11) -> 3.1074464 | T19: =1-($P$6*56*0.3048*D19*$B$26*$B$25*$B$13)/(2*$B$5*$B$11) -> -1.1074464 | U19: =1+($P$6*28*0.3048*D19*$B$26*$B$25*$B$13)/(2*$B$5*$B$11) -> 2.0537232 | V19: =1-($P$6*28*0.3048*D19*$B$26*$B$25*$B$13)/(2*$B$5*$B$11) -> -0.053723195
A20: Compressibility factor beta | B20: 1 | D20: 140 | E20: =1.94384*D20 -> 272.1376 | F20: =E20/$B$9 -> 0.41140715 | G20: =(0.5*$B$26*D20^2)*0.020885434273039 -> 250.72964 | H20: 1 | I20: =H20*$B$10 -> 2.2 | J20: =$B$28*$H$6 -> -1.1 | K20: =((G20/0.020885434273039)*I20*$B$13)/($B$5*$B$11) -> 10.093744 | L20: =((G20/0.020885434273039)*J20*$B$13)/($B$5*$B$11) -> -5.0468721 | O20: =2*$B$5/($B$26*$B$27*$B$25*$B$13) -> 39.37849 | P20: =(0.88*O20)/(5.3+O20) -> 0.77560972 | S20: =1+($P$6*56*0.3048*D20*$B$26*$B$25*$B$13)/(2*$B$5*$B$11) -> 3.2695577 | T20: =1-($P$6*56*0.3048*D20*$B$26*$B$25*$B$13)/(2*$B$5*$B$11) -> -1.2695577 | U20: =1+($P$6*28*0.3048*D20*$B$26*$B$25*$B$13)/(2*$B$5*$B$11) -> 2.1347788 | V20: =1-($P$6*28*0.3048*D20*$B$26*$B$25*$B$13)/(2*$B$5*$B$11) -> -0.13477883
A21: compressible swept parameter Λ_beta | B21: 0 | D21: 150 | E21: =1.94384*D21 -> 291.576 | F21: =E21/$B$9 -> 0.44079337 | G21: =(0.5*$B$26*D21^2)*0.020885434273039 -> 287.82739 | H21: 1 | I21: =H21*$B$10 -> 2.2 | J21: =$B$28*$H$6 -> -1.1 | K21: =((G21/0.020885434273039)*I21*$B$13)/($B$5*$B$11) -> 11.587206 | L21: =((G21/0.020885434273039)*J21*$B$13)/($B$5*$B$11) -> -5.7936031 | O21: =2*$B$5/($B$26*$B$27*$B$25*$B$13) -> 39.37849 | P21: =(0.88*O21)/(5.3+O21) -> 0.77560972 | S21: =1+($P$6*56*0.3048*D21*$B$26*$B$25*$B$13)/(2*$B$5*$B$11) -> 3.4316689 | T21: =1-($P$6*56*0.3048*D21*$B$26*$B$25*$B$13)/(2*$B$5*$B$11) -> -1.4316689 | U21: =1+($P$6*28*0.3048*D21*$B$26*$B$25*$B$13)/(2*$B$5*$B$11) -> 2.2158345 | V21: =1-($P$6*28*0.3048*D21*$B$26*$B$25*$B$13)/(2*$B$5*$B$11) -> -0.21583446
A22: k factor assume =1 | B22: 1 | D22: 160 | E22: =1.94384*D22 -> 311.0144 | F22: =E22/$B$9 -> 0.4701796 | G22: =(0.5*$B$26*D22^2)*0.020885434273039 -> 327.48361 | H22: 1 | I22: =H22*$B$10 -> 2.2 | J22: =$B$28*$H$6 -> -1.1 | K22: =((G22/0.020885434273039)*I22*$B$13)/($B$5*$B$11) -> 13.183666 | L22: =((G22/0.020885434273039)*J22*$B$13)/($B$5*$B$11) -> -6.5918329 | O22: =2*$B$5/($B$26*$B$27*$B$25*$B$13) -> 39.37849 | P22: =(0.88*O22)/(5.3+O22) -> 0.77560972 | S22: =1+($P$6*56*0.3048*D22*$B$26*$B$25*$B$13)/(2*$B$5*$B$11) -> 3.5937802 | T22: =1-($P$6*56*0.3048*D22*$B$26*$B$25*$B$13)/(2*$B$5*$B$11) -> -1.5937802 | U22: =1+($P$6*28*0.3048*D22*$B$26*$B$25*$B$13)/(2*$B$5*$B$11) -> 2.2968901 | V22: =1-($P$6*28*0.3048*D22*$B$26*$B$25*$B$13)/(2*$B$5*$B$11) -> -0.29689009
A23: β*AR/K | B23: =B20*B17/B22 -> 8.4 | D23: 170 | E23: =1.94384*D23 -> 330.4528 | F23: =E23/$B$9 -> 0.49956582 | G23: =(0.5*$B$26*D23^2)*0.020885434273039 -> 369.69829 | H23: 1 | I23: =H23*$B$10 -> 2.2 | J23: =$B$28*$H$6 -> -1.1 | K23: =((G23/0.020885434273039)*I23*$B$13)/($B$5*$B$11) -> 14.883123 | L23: =((G23/0.020885434273039)*J23*$B$13)/($B$5*$B$11) -> -7.4415614 | O23: =2*$B$5/($B$26*$B$27*$B$25*$B$13) -> 39.37849 | P23: =(0.88*O23)/(5.3+O23) -> 0.77560972 | S23: =1+($P$6*56*0.3048*D23*$B$26*$B$25*$B$13)/(2*$B$5*$B$11) -> 3.7558914 | T23: =1-($P$6*56*0.3048*D23*$B$26*$B$25*$B$13)/(2*$B$5*$B$11) -> -1.7558914 | U23: =1+($P$6*28*0.3048*D23*$B$26*$B$25*$B$13)/(2*$B$5*$B$11) -> 2.3779457 | V23: =1-($P$6*28*0.3048*D23*$B$26*$B$25*$B$13)/(2*$B$5*$B$11) -> -0.37794572
A24: cl alpha w (1/rad) tablas | B24: =0.083*180/PI() -> 4.7555497 | D24: 180 | E24: =1.94384*D24 -> 349.8912 | F24: =E24/$B$9 -> 0.52895205 | G24: =(0.5*$B$26*D24^2)*0.020885434273039 -> 414.47144 | H24: 1 | I24: =H24*$B$10 -> 2.2 | J24: =$B$28*$H$6 -> -1.1 | K24: =((G24/0.020885434273039)*I24*$B$13)/($B$5*$B$11) -> 16.685577 | L24: =((G24/0.020885434273039)*J24*$B$13)/($B$5*$B$11) -> -8.3427885 | O24: =2*$B$5/($B$26*$B$27*$B$25*$B$13) -> 39.37849 | P24: =(0.88*O24)/(5.3+O24) -> 0.77560972 | S24: =1+($P$6*56*0.3048*D24*$B$26*$B$25*$B$13)/(2*$B$5*$B$11) -> 3.9180027 | T24: =1-($P$6*56*0.3048*D24*$B$26*$B$25*$B$13)/(2*$B$5*$B$11) -> -1.9180027 | U24: =1+($P$6*28*0.3048*D24*$B$26*$B$25*$B$13)/(2*$B$5*$B$11) -> 2.4590013 | V24: =1-($P$6*28*0.3048*D24*$B$26*$B$25*$B$13)/(2*$B$5*$B$11) -> -0.45900135
A25: cl alpha aircraft (1/rad) at M=0 | B25: =1.1*B24 -> 5.2311047 | D25: 190 | E25: =1.94384*D25 -> 369.3296 | F25: =E25/$B$9 -> 0.55833827 | G25: =(0.5*$B$26*D25^2)*0.020885434273039 -> 461.80306 | H25: 1 | I25: =H25*$B$10 -> 2.2 | J25: =$B$28*$H$6 -> -1.1 | K25: =((G25/0.020885434273039)*I25*$B$13)/($B$5*$B$11) -> 18.591029 | L25: =((G25/0.020885434273039)*J25*$B$13)/($B$5*$B$11) -> -9.2955144 | O25: =2*$B$5/($B$26*$B$27*$B$25*$B$13) -> 39.37849 | P25: =(0.88*O25)/(5.3+O25) -> 0.77560972 | S25: =1+($P$6*56*0.3048*D25*$B$26*$B$25*$B$13)/(2*$B$5*$B$11) -> 4.080114 | T25: =1-($P$6*56*0.3048*D25*$B$26*$B$25*$B$13)/(2*$B$5*$B$11) -> -2.080114 | U25: =1+($P$6*28*0.3048*D25*$B$26*$B$25*$B$13)/(2*$B$5*$B$11) -> 2.540057 | V25: =1-($P$6*28*0.3048*D25*$B$26*$B$25*$B$13)/(2*$B$5*$B$11) -> -0.54005698
A26: Air density at h ft (kg/m^3) | B26: 1.225 | D26: 200 | E26: =1.94384*D26 -> 388.768 | F26: =E26/$B$9 -> 0.5877245 | G26: =(0.5*$B$26*D26^2)*0.020885434273039 -> 511.69314 | H26: 1 | I26: =H26*$B$10 -> 2.2 | J26: =$B$28*$H$6 -> -1.1 | K26: =((G26/0.020885434273039)*I26*$B$13)/($B$5*$B$11) -> 20.599478 | L26: =((G26/0.020885434273039)*J26*$B$13)/($B$5*$B$11) -> -10.299739 | O26: =2*$B$5/($B$26*$B$27*$B$25*$B$13) -> 39.37849 | P26: =(0.88*O26)/(5.3+O26) -> 0.77560972 | S26: =1+($P$6*56*0.3048*D26*$B$26*$B$25*$B$13)/(2*$B$5*$B$11) -> 4.2422252 | T26: =1-($P$6*56*0.3048*D26*$B$26*$B$25*$B$13)/(2*$B$5*$B$11) -> -2.2422252 | U26: =1+($P$6*28*0.3048*D26*$B$26*$B$25*$B$13)/(2*$B$5*$B$11) -> 2.6211126 | V26: =1-($P$6*28*0.3048*D26*$B$26*$B$25*$B$13)/(2*$B$5*$B$11) -> -0.62111261
A27: mean aerodynamic chord (c_bar) (m) | B27: 2.114 | D27: 210 | E27: =1.94384*D27 -> 408.2064 | F27: =E27/$B$9 -> 0.61711072 | G27: =(0.5*$B$26*D27^2)*0.020885434273039 -> 564.14169 | H27: 1 | I27: =H27*$B$10 -> 2.2 | J27: =$B$28*$H$6 -> -1.1 | K27: =((G27/0.020885434273039)*I27*$B$13)/($B$5*$B$11) -> 22.710924 | L27: =((G27/0.020885434273039)*J27*$B$13)/($B$5*$B$11) -> -11.355462 | O27: =2*$B$5/($B$26*$B$27*$B$25*$B$13) -> 39.37849 | P27: =(0.88*O27)/(5.3+O27) -> 0.77560972 | S27: =1+($P$6*56*0.3048*D27*$B$26*$B$25*$B$13)/(2*$B$5*$B$11) -> 4.4043365 | T27: =1-($P$6*56*0.3048*D27*$B$26*$B$25*$B$13)/(2*$B$5*$B$11) -> -2.4043365 | U27: =1+($P$6*28*0.3048*D27*$B$26*$B$25*$B$13)/(2*$B$5*$B$11) -> 2.7021682 | V27: =1-($P$6*28*0.3048*D27*$B$26*$B$25*$B$13)/(2*$B$5*$B$11) -> -0.70216824
A28: negative Cl max (-) M=0 | B28: =-0.5*B10 -> -1.1 | D28: =0.514444*B7 -> 226.8698 | E28: =1.94384*D28 -> 440.9986 | F28: =E28/$B$9 -> 0.66668471 | G28: =(0.5*$B$26*D28^2)*0.020885434273039 -> 658.41997 | H28: 1 | I28: =H28*$B$10 -> 2.2 | J28: =$B$28*$H$6 -> -1.1 | K28: =((G28/0.020885434273039)*I28*$B$13)/($B$5*$B$11) -> 26.506331 | L28: =((G28/0.020885434273039)*J28*$B$13)/($B$5*$B$11) -> -13.253165 | O28: =2*$B$5/($B$26*$B$27*$B$25*$B$13) -> 39.37849 | P28: =(0.88*O28)/(5.3+O28) -> 0.77560972 | S28: =1+($P$6*56*0.3048*D28*$B$26*$B$25*$B$13)/(2*$B$5*$B$11) -> 4.677815 | T28: =1-($P$6*56*0.3048*D28*$B$26*$B$25*$B$13)/(2*$B$5*$B$11) -> -2.677815 | U28: =1+($P$6*28*0.3048*D28*$B$26*$B$25*$B$13)/(2*$B$5*$B$11) -> 2.8389075 | V28: =1-($P$6*28*0.3048*D28*$B$26*$B$25*$B$13)/(2*$B$5*$B$11) -> -0.8389075
D29: 283.5875 | E29: 551.25 | F29: =E29/$B$9 -> 0.83335853 | G29: =(0.5*$B$26*D29^2)*0.020885434273039 -> 1028.783 | H29: 2 | I29: =H29*$B$10 -> 4.4 | J29: =$B$28*$H$6 -> -1.1 | K29: =((G29/0.020885434273039)*I29*$B$13)/($B$5*$B$11) -> 82.832427 | L29: =((G29/0.020885434273039)*J29*$B$13)/($B$5*$B$11) -> -20.708107 | O29: =2*$B$5/($B$26*$B$27*$B$25*$B$13) -> 39.37849 | P29: =(0.88*O29)/(5.3+O29) -> 0.77560972 | U29: =1+($P$6*28*0.3048*D29*$B$26*$B$25*$B$13)/(2*$B$5*$B$11) -> 3.2986364 | V29: =1-($P$6*28*0.3048*D29*$B$26*$B$25*$B$13)/(2*$B$5*$B$11) -> -1.2986364
A30: Speeds | B30: n+ | D30: n- | G30: n+ | H30: n-
A31: V stall KEAS | B31: =SQRT((2*B5*B11)/(B26*B13*B10))*1.94384 -> 85.65691 | D31: =SQRT((2*B5*B11)/(B26*B13*-B28))*1.94384 -> 121.13716 | F31: V stall m/s | G31: =SQRT((2*B5*B11)/(B26*B13*2.2)) -> 44.065823 | H31: =SQRT((2*B5*B11)/(B26*B13*1.1)) -> 62.318485
A32: V flaps KEAS | B32: =SQRT((2*B5*B11)/(B26*B13*B10*1.15))*1.94384 -> 79.875481 | F32: V stall flaps m/s | G32: =SQRT((2*B5*B11)/(B26*B13*2.2*1.15)) -> 41.091592
A33: V maneuver (V_A) KEAS | B33: =SQRT(B15)*B31 -> 145.736 | D33: =D31*SQRT(B16*-1) -> 121.13716
A34: V cruise KEAS | B34: =B7 -> 441 | F34: V cruise m/s | G34: =B34/1.94384 -> 226.87052
A35: V NE | B35: =B8*0.9 -> 496.125 | F35: VgE m/s | G35: 10.90344
A36: V dive KEAS | B36: =B8 -> 551.25
A37: V_B KEAS | B37: =B31*(1+(P10*56*0.3048*B7*0.514444*B26*B25*B13)/(2*B5*B11))^0.5 -> 185.26097 | D37: =D31*(1+(P23*56*0.3048*B7*0.514444*B26*B25*B13)/(2*B5*B11))^0.5 -> 261.99857
A39: Loads
A40: n2 load factor | B40: =0.75*B15 -> 2.1710516
A41: proof load | B41: =1.25*B15 -> 3.6184193
A42: Ultimate load | B42: =1.5*B15 -> 4.3421032
A45: Plot | B45: x | C45: y
...

Sheet V-n CL
A1: CESSNA CITATION XLS+ | B1: MIDTERM 2
A4: Masa (lb) | B4: =B5/0.453592 -> 20198.769 | D4: MANEUVER | M4: GUST
A5: Masa (kg) | B5: 9162 | D5: V eq. m/s | E5: V eq. KEAS | F5: Mach (Ve/Cse) | G5: q dynamic pressure (lb/ft^2) | H5: Clmax_m/Clmax_0 | I5: Cl max_m | J5: Cl max_m (-) | K5: positive load factor n | L5: negative load factor | M5: Cl alpha_m/cl alpha 0 | N5: Cl alpha_m | O5: μ | P5: Kg | Q5: positive gust load factor VB | R5: negative gust load factor VB | S5: positive gust load factor Vc | T5: negative gust load factor Vc | U5: positive gust load factor Vd | V5: negative gust load factor Vd | X5: positive load factor with flaps extended
A6: h (ft) | B6: 31000 | D6: 0 | E6: =1.94384*D6 -> 0 | F6: =E6/$B$9 -> 0 | G6: =(0.5*$B$26*D6^2)*0.020885434273039 -> 0 | H6: 1 | I6: =H6*$B$10 -> 2.2 | J6: =$B$28*$H$6 -> -1.1 | K6: =((G6/0.020885434273039)*I6*$B$13)/($B$5*$B$11) -> 0 | L6: =((G6/0.020885434273039)*J6*$B$13)/($B$5*$B$11) -> 0 | O6: =2*$B$5/($B$26*$B$27*$B$25*$B$13) -> 39.37849 | P6: =(0.88*O6)/(5.3+O6) -> 0.77560972 | Q6: Does not apply | R6: Does not apply | S6: =1+($P$6*56*0.3048*D6*$B$26*$B$25*$B$13)/(2*$B$5*$B$11) -> 1 | T6: =1-($P$6*56*0.3048*D6*$B$26*$B$25*$B$13)/(2*$B$5*$B$11) -> 1 | U6: =1+($P$6*28*0.3048*D6*$B$26*$B$25*$B$13)/(2*$B$5*$B$11) -> 1 | V6: =1-($P$6*28*0.3048*D6*$B$26*$B$25*$B$13)/(2*$B$5*$B$11) -> 1 | X6: =((G6/0.020885434273039)*I6*1.15*$B$13)/($B$5*$B$11) -> 0
A7: Vc KEAS | B7: =441*SQRT(0.36115) -> 265.02229 | D7: 10.29 | E7: =1.94384*D7 -> 20.002114 | F7: =E7/$B$9 -> 0.056713016 | G7: =(0.5*$B$26*D7^2)*0.020885434273039 -> 1.3545042 | H7: 1 | I7: =H7*$B$10 -> 2.2 | J7: =$B$28*$H$6 -> -1.1 | K7: =((G7/0.020885434273039)*I7*$B$13)/($B$5*$B$11) -> 0.054528929 | L7: =((G7/0.020885434273039)*J7*$B$13)/($B$5*$B$11) -> -0.027264465 | O7: =2*$B$5/($B$26*$B$27*$B$25*$B$13) -> 39.37849 | P7: =(0.88*O7)/(5.3+O7) -> 0.77560972 | S7: =1+($P$6*56*0.3048*D7*$B$26*$B$25*$B$13)/(2*$B$5*$B$11) -> 1.1668125 | T7: =1-($P$6*56*0.3048*D7*$B$26*$B$25*$B$13)/(2*$B$5*$B$11) -> 0.83318751 | U7: =1+($P$6*28*0.3048*D7*$B$26*$B$25*$B$13)/(2*$B$5*$B$11) -> 1.0834062 | V7: =1-($P$6*28*0.3048*D7*$B$26*$B$25*$B$13)/(2*$B$5*$B$11) -> 0.91659376 | X7: =((G7/0.020885434273039)*I7*1.15*$B$13)/($B$5*$B$11) -> 0.062708269
A8: Vd KEAS | B8: =1.25*B7 -> 331.27786 | D8: 20 | E8: =1.94384*D8 -> 38.8768 | F8: =E8/$B$9 -> 0.11022938 | G8: =(0.5*$B$26*D8^2)*0.020885434273039 -> 5.1169314 | H8: 1 | I8: =H8*$B$10 -> 2.2 | J8: =$B$28*$H$6 -> -1.1 | K8: =((G8/0.020885434273039)*I8*$B$13)/($B$5*$B$11) -> 0.20599478 | L8: =((G8/0.020885434273039)*J8*$B$13)/($B$5*$B$11) -> -0.10299739 | O8: =2*$B$5/($B$26*$B$27*$B$25*$B$13) -> 39.37849 | P8: =(0.88*O8)/(5.3+O8) -> 0.77560972 | S8: =1+($P$6*56*0.3048*D8*$B$26*$B$25*$B$13)/(2*$B$5*$B$11) -> 1.3242225 | T8: =1-($P$6*56*0.3048*D8*$B$26*$B$25*$B$13)/(2*$B$5*$B$11) -> 0.67577748 | U8: =1+($P$6*28*0.3048*D8*$B$26*$B$25*$B$13)/(2*$B$5*$B$11) -> 1.1621113 | V8: =1-($P$6*28*0.3048*D8*$B$26*$B$25*$B$13)/(2*$B$5*$B$11) -> 0.83788874 | X8: =((G8/0.020885434273039)*I8*1.15*$B$13)/($B$5*$B$11) -> 0.236894
A9: Cse KEAS (h ft) | B9: 352.69 | D9: 30 | E9: =1.94384*D9 -> 58.3152 | F9: =E9/$B$9 -> 0.16534407 | G9: =(0.5*$B$26*D9^2)*0.020885434273039 -> 11.513096 | H9: 1 | I9: =H9*$B$10 -> 2.2 | J9: =$B$28*$H$6 -> -1.1 | K9: =((G9/0.020885434273039)*I9*$B$13)/($B$5*$B$11) -> 0.46348825 | L9: =((G9/0.020885434273039)*J9*$B$13)/($B$5*$B$11) -> -0.23174413 | O9: =2*$B$5/($B$26*$B$27*$B$25*$B$13) -> 39.37849 | P9: =(0.88*O9)/(5.3+O9) -> 0.77560972 | S9: =1+($P$6*56*0.3048*D9*$B$26*$B$25*$B$13)/(2*$B$5*$B$11) -> 1.4863338 | T9: =1-($P$6*56*0.3048*D9*$B$26*$B$25*$B$13)/(2*$B$5*$B$11) -> 0.51366622 | U9: =1+($P$6*28*0.3048*D9*$B$26*$B$25*$B$13)/(2*$B$5*$B$11) -> 1.2431669 | V9: =1-($P$6*28*0.3048*D9*$B$26*$B$25*$B$13)/(2*$B$5*$B$11) -> 0.75683311 | X9: =((G9/0.020885434273039)*I9*1.15*$B$13)/($B$5*$B$11) -> 0.53301149
A10: (Clmax)0 at M=0 | B10: 2.2 | D10: 40 | E10: =1.94384*D10 -> 77.7536 | F10: =E10/$B$9 -> 0.22045876 | G10: =(0.5*$B$26*D10^2)*0.020885434273039 -> 20.467726 | H10: 1 | I10: =H10*$B$10 -> 2.2 | J10: =$B$28*$H$6 -> -1.1 | K10: =((G10/0.020885434273039)*I10*$B$13)/($B$5*$B$11) -> 0.82397911 | L10: =((G10/0.020885434273039)*J10*$B$13)/($B$5*$B$11) -> -0.41198956 | O10: =2*$B$5/($B$26*$B$27*$B$25*$B$13) -> 39.37849 | P10: =(0.88*O10)/(5.3+O10) -> 0.77560972 | S10: =1+($P$6*56*0.3048*D10*$B$26*$B$25*$B$13)/(2*$B$5*$B$11) -> 1.648445 | T10: =1-($P$6*56*0.3048*D10*$B$26*$B$25*$B$13)/(2*$B$5*$B$11) -> 0.35155496 | U10: =1+($P$6*28*0.3048*D10*$B$26*$B$25*$B$13)/(2*$B$5*$B$11) -> 1.3242225 | V10: =1-($P$6*28*0.3048*D10*$B$26*$B$25*$B$13)/(2*$B$5*$B$11) -> 0.67577748 | X10: =((G10/0.020885434273039)*I10*1.15*$B$13)/($B$5*$B$11) -> 0.94757598
A11: Gravity m/s^2 | B11: 9.81 | D11: 44.065946 | E11: =1.94384*D11 -> 85.657149 | F11: =E11/$B$9 -> 0.2428681 | G11: =(0.5*$B$26*D11^2)*0.020885434273039 -> 24.840241 | H11: 1 | I11: =H11*$B$10 -> 2.2 | J11: =$B$28*$H$6 -> -1.1 | K11: =((G11/0.020885434273039)*I11*$B$13)/($B$5*$B$11) -> 1.0000056 | L11: =((G11/0.020885434273039)*J11*$B$13)/($B$5*$B$11) -> -0.50000279 | O11: =2*$B$5/($B$26*$B$27*$B$25*$B$13) -> 39.37849 | P11: =(0.88*O11)/(5.3+O11) -> 0.77560972 | S11: =1+($P$6*56*0.3048*D11*$B$26*$B$25*$B$13)/(2*$B$5*$B$11) -> 1.7143586 | T11: =1-($P$6*56*0.3048*D11*$B$26*$B$25*$B$13)/(2*$B$5*$B$11) -> 0.28564139 | U11: =1+($P$6*28*0.3048*D11*$B$26*$B$25*$B$13)/(2*$B$5*$B$11) -> 1.3571793 | V11: =1-($P$6*28*0.3048*D11*$B$26*$B$25*$B$13)/(2*$B$5*$B$11) -> 0.64282069 | X11: =((G11/0.020885434273039)*I11*1.15*$B$13)/($B$5*$B$11) -> 1.1500064
A12: span b (m) | B12: 16.97 | D12: 58.115916 | E12: =1.94384*D12 -> 112.96804 | F12: =E12/$B$9 -> 0.32030407 | G12: =(0.5*$B$26*D12^2)*0.020885434273039 -> 43.205575 | H12: 1 | I12: =H12*$B$10 -> 2.2 | J12: =$B$28*$H$6 -> -1.1 | K12: =((G12/0.020885434273039)*I12*$B$13)/($B$5*$B$11) -> 1.7393477 | L12: =((G12/0.020885434273039)*J12*$B$13)/($B$5*$B$11) -> -0.86967384 | O12: =2*$B$5/($B$26*$B$27*$B$25*$B$13) -> 39.37849 | P12: =(0.88*O12)/(5.3+O12) -> 0.77560972 | S12: =1+($P$6*56*0.3048*D12*$B$26*$B$25*$B$13)/(2*$B$5*$B$11) -> 1.9421244 | T12: =1-($P$6*56*0.3048*D12*$B$26*$B$25*$B$13)/(2*$B$5*$B$11) -> 0.057875551 | U12: =1+($P$6*28*0.3048*D12*$B$26*$B$25*$B$13)/(2*$B$5*$B$11) -> 1.4710622 | V12: =1-($P$6*28*0.3048*D12*$B$26*$B$25*$B$13)/(2*$B$5*$B$11) -> 0.52893778 | X12: =((G12/0.020885434273039)*I12*1.15*$B$13)/($B$5*$B$11) -> 2.0002498
A13: wing area S (m^2) | B13: 34.35 | D13: 62.338847 | E13: =1.94384*D13 -> 121.17674 | F13: =E13/$B$9 -> 0.34357862 | G13: =(0.5*$B$26*D13^2)*0.020885434273039 -> 49.712675 | H13: 1 | I13: =H13*$B$10 -> 2.2 | J13: =$B$28*$H$6 -> -1.1 | K13: =((G13/0.020885434273039)*I13*$B$13)/($B$5*$B$11) -> 2.0013071 | L13: =((G13/0.020885434273039)*J13*$B$13)/($B$5*$B$11) -> -1.0006536 | O13: =2*$B$5/($B$26*$B$27*$B$25*$B$13) -> 39.37849 | P13: =(0.88*O13)/(5.3+O13) -> 0.77560972 | S13: =1+($P$6*56*0.3048*D13*$B$26*$B$25*$B$13)/(2*$B$5*$B$11) -> 2.0105829 | T13: =1-($P$6*56*0.3048*D13*$B$26*$B$25*$B$13)/(2*$B$5*$B$11) -> -0.010582902 | U13: =1+($P$6*28*0.3048*D13*$B$26*$B$25*$B$13)/(2*$B$5*$B$11) -> 1.5052915 | V13: =1-($P$6*28*0.3048*D13*$B$26*$B$25*$B$13)/(2*$B$5*$B$11) -> 0.49470855
A14: Wing load W/S (kg/m^2) | B14: =B5/B13 -> 266.72489 | D14: 74.912593 | E14: =1.94384*D14 -> 145.6181 | F14: =E14/$B$9 -> 0.41287843 | G14: =(0.5*$B$26*D14^2)*0.020885434273039 -> 71.789225 | H14: 1 | I14: =H14*$B$10 -> 2.2 | J14: =$B$28*$H$6 -> -1.1 | K14: =((G14/0.020885434273039)*I14*$B$13)/($B$5*$B$11) -> 2.8900535 | L14: =((G14/0.020885434273039)*J14*$B$13)/($B$5*$B$11) -> -1.4450268 | O14: =2*$B$5/($B$26*$B$27*$B$25*$B$13) -> 39.37849 | P14: =(0.88*O14)/(5.3+O14) -> 0.77560972 | S14: =1+($P$6*56*0.3048*D14*$B$26*$B$25*$B$13)/(2*$B$5*$B$11) -> 2.2144175 | T14: =1-($P$6*56*0.3048*D14*$B$26*$B$25*$B$13)/(2*$B$5*$B$11) -> -0.21441749 | U14: =1+($P$6*28*0.3048*D14*$B$26*$B$25*$B$13)/(2*$B$5*$B$11) -> 1.6072087 | V14: =1-($P$6*28*0.3048*D14*$B$26*$B$25*$B$13)/(2*$B$5*$B$11) -> 0.39279125
A15: positive load factor n1 | B15: =2.1+(24000/(B4+10000)) -> 2.8947344 | D15: 90 | E15: =1.94384*D15 -> 174.9456 | F15: =E15/$B$9 -> 0.49603221 | G15: =(0.5*$B$26*D15^2)*0.020885434273039 -> 103.61786 | H15: 1 | I15: =H15*$B$10 -> 2.2 | J15: =$B$28*$H$6 -> -1.1 | K15: =((G15/0.020885434273039)*I15*$B$13)/($B$5*$B$11) -> 4.1713943 | L15: =((G15/0.020885434273039)*J15*$B$13)/($B$5*$B$11) -> -2.0856971 | O15: =2*$B$5/($B$26*$B$27*$B$25*$B$13) -> 39.37849 | P15: =(0.88*O15)/(5.3+O15) -> 0.77560972 | S15: =1+($P$6*56*0.3048*D15*$B$26*$B$25*$B$13)/(2*$B$5*$B$11) -> 2.4590013 | T15: =1-($P$6*56*0.3048*D15*$B$26*$B$25*$B$13)/(2*$B$5*$B$11) -> -0.45900135 | U15: =1+($P$6*28*0.3048*D15*$B$26*$B$25*$B$13)/(2*$B$5*$B$11) -> 1.7295007 | V15: =1-($P$6*28*0.3048*D15*$B$26*$B$25*$B$13)/(2*$B$5*$B$11) -> 0.27049933
A16: negative limit load factor | B16: -1 | D16: 100 | E16: =1.94384*D16 -> 194.384 | F16: =E16/$B$9 -> 0.5511469 | G16: =(0.5*$B$26*D16^2)*0.020885434273039 -> 127.92328 | H16: 1 | I16: =H16*$B$10 -> 2.2 | J16: =$B$28*$H$6 -> -1.1 | K16: =((G16/0.020885434273039)*I16*$B$13)/($B$5*$B$11) -> 5.1498695 | L16: =((G16/0.020885434273039)*J16*$B$13)/($B$5*$B$11) -> -2.5749347 | O16: =2*$B$5/($B$26*$B$27*$B$25*$B$13) -> 39.37849 | P16: =(0.88*O16)/(5.3+O16) -> 0.77560972 | S16: =1+($P$6*56*0.3048*D16*$B$26*$B$25*$B$13)/(2*$B$5*$B$11) -> 2.6211126 | T16: =1-($P$6*56*0.3048*D16*$B$26*$B$25*$B$13)/(2*$B$5*$B$11) -> -0.62111261 | U16: =1+($P$6*28*0.3048*D16*$B$26*$B$25*$B$13)/(2*$B$5*$B$11) -> 1.8105563 | V16: =1-($P$6*28*0.3048*D16*$B$26*$B$25*$B$13)/(2*$B$5*$B$11) -> 0.1894437
A17: Aspect ratio | B17: 8.4 | D17: 110 | E17: =1.94384*D17 -> 213.8224 | F17: =E17/$B$9 -> 0.60626159 | G17: =(0.5*$B$26*D17^2)*0.020885434273039 -> 154.78717 | H17: 1 | I17: =H17*$B$10 -> 2.2 | J17: =$B$28*$H$6 -> -1.1 | K17: =((G17/0.020885434273039)*I17*$B$13)/($B$5*$B$11) -> 6.231342 | L17: =((G17/0.020885434273039)*J17*$B$13)/($B$5*$B$11) -> -3.115671 | O17: =2*$B$5/($B$26*$B$27*$B$25*$B$13) -> 39.37849 | P17: =(0.88*O17)/(5.3+O17) -> 0.77560972 | S17: =1+($P$6*56*0.3048*D17*$B$26*$B$25*$B$13)/(2*$B$5*$B$11) -> 2.7832239 | T17: =1-($P$6*56*0.3048*D17*$B$26*$B$25*$B$13)/(2*$B$5*$B$11) -> -0.78322387 | U17: =1+($P$6*28*0.3048*D17*$B$26*$B$25*$B$13)/(2*$B$5*$B$11) -> 1.8916119 | V17: =1-($P$6*28*0.3048*D17*$B$26*$B$25*$B$13)/(2*$B$5*$B$11) -> 0.10838807
A18: Taper ratio (lambda) | B18: 0.2 | D18: 120 | E18: =1.94384*D18 -> 233.2608 | F18: =E18/$B$9 -> 0.66137628 | G18: =(0.5*$B$26*D18^2)*0.020885434273039 -> 184.20953 | H18: 1 | I18: =H18*$B$10 -> 2.2 | J18: =$B$28*$H$6 -> -1.1 | K18: =((G18/0.020885434273039)*I18*$B$13)/($B$5*$B$11) -> 7.415812 | L18: =((G18/0.020885434273039)*J18*$B$13)/($B$5*$B$11) -> -3.707906 | O18: =2*$B$5/($B$26*$B$27*$B$25*$B$13) -> 39.37849 | P18: =(0.88*O18)/(5.3+O18) -> 0.77560972 | S18: =1+($P$6*56*0.3048*D18*$B$26*$B$25*$B$13)/(2*$B$5*$B$11) -> 2.9453351 | T18: =1-($P$6*56*0.3048*D18*$B$26*$B$25*$B$13)/(2*$B$5*$B$11) -> -0.94533513 | U18: =1+($P$6*28*0.3048*D18*$B$26*$B$25*$B$13)/(2*$B$5*$B$11) -> 1.9726676 | V18: =1-($P$6*28*0.3048*D18*$B$26*$B$25*$B$13)/(2*$B$5*$B$11) -> 0.027332435
A19: aflechamiento (Swept)Λ | B19: 0 | D19: 130 | E19: =1.94384*D19 -> 252.6992 | F19: =E19/$B$9 -> 0.71649097 | G19: =(0.5*$B$26*D19^2)*0.020885434273039 -> 216.19035 | H19: 1 | I19: =H19*$B$10 -> 2.2 | J19: =$B$28*$H$6 -> -1.1 | K19: =((G19/0.020885434273039)*I19*$B$13)/($B$5*$B$11) -> 8.7032794 | L19: =((G19/0.020885434273039)*J19*$B$13)/($B$5*$B$11) -> -4.3516397 | O19: =2*$B$5/($B$26*$B$27*$B$25*$B$13) -> 39.37849 | P19: =(0.88*O19)/(5.3+O19) -> 0.77560972 | S19: =1+($P$6*56*0.3048*D19*$B$26*$B$25*$B$13)/(2*$B$5*$B$11) -> 3.1074464 | T19: =1-($P$6*56*0.3048*D19*$B$26*$B$25*$B$13)/(2*$B$5*$B$11) -> -1.1074464 | U19: =1+($P$6*28*0.3048*D19*$B$26*$B$25*$B$13)/(2*$B$5*$B$11) -> 2.0537232 | V19: =1-($P$6*28*0.3048*D19*$B$26*$B$25*$B$13)/(2*$B$5*$B$11) -> -0.053723195
A20: Compressibility factor beta | B20: 1 | D20: 140 | E20: =1.94384*D20 -> 272.1376 | F20: =E20/$B$9 -> 0.77160566 | G20: =(0.5*$B$26*D20^2)*0.020885434273039 -> 250.72964 | H20: 1 | I20: =H20*$B$10 -> 2.2 | J20: =$B$28*$H$6 -> -1.1 | K20: =((G20/0.020885434273039)*I20*$B$13)/($B$5*$B$11) -> 10.093744 | L20: =((G20/0.020885434273039)*J20*$B$13)/($B$5*$B$11) -> -5.0468721 | O20: =2*$B$5/($B$26*$B$27*$B$25*$B$13) -> 39.37849 | P20: =(0.88*O20)/(5.3+O20) -> 0.77560972 | S20: =1+($P$6*56*0.3048*D20*$B$26*$B$25*$B$13)/(2*$B$5*$B$11) -> 3.2695577 | T20: =1-($P$6*56*0.3048*D20*$B$26*$B$25*$B$13)/(2*$B$5*$B$11) -> -1.2695577 | U20: =1+($P$6*28*0.3048*D20*$B$26*$B$25*$B$13)/(2*$B$5*$B$11) -> 2.1347788 | V20: =1-($P$6*28*0.3048*D20*$B$26*$B$25*$B$13)/(2*$B$5*$B$11) -> -0.13477883
A21: compressible swept parameter Λ_beta | B21: 0 | D21: 150 | E21: =1.94384*D21 -> 291.576 | F21: =E21/$B$9 -> 0.82672035 | G21: =(0.5*$B$26*D21^2)*0.020885434273039 -> 287.82739 | H21: 1 | I21: =H21*$B$10 -> 2.2 | J21: =$B$28*$H$6 -> -1.1 | K21: =((G21/0.020885434273039)*I21*$B$13)/($B$5*$B$11) -> 11.587206 | L21: =((G21/0.020885434273039)*J21*$B$13)/($B$5*$B$11) -> -5.7936031 | O21: =2*$B$5/($B$26*$B$27*$B$25*$B$13) -> 39.37849 | P21: =(0.88*O21)/(5.3+O21) -> 0.77560972 | S21: =1+($P$6*56*0.3048*D21*$B$26*$B$25*$B$13)/(2*$B$5*$B$11) -> 3.4316689 | T21: =1-($P$6*56*0.3048*D21*$B$26*$B$25*$B$13)/(2*$B$5*$B$11) -> -1.4316689 | U21: =1+($P$6*28*0.3048*D21*$B$26*$B$25*$B$13)/(2*$B$5*$B$11) -> 2.2158345 | V21: =1-($P$6*28*0.3048*D21*$B$26*$B$25*$B$13)/(2*$B$5*$B$11) -> -0.21583446
A22: k factor assume =1 | B22: 1 | D22: 160 | E22: =1.94384*D22 -> 311.0144 | F22: =E22/$B$9 -> 0.88183504 | G22: =(0.5*$B$26*D22^2)*0.020885434273039 -> 327.48361 | H22: 1 | I22: =H22*$B$10 -> 2.2 | J22: =$B$28*$H$6 -> -1.1 | K22: =((G22/0.020885434273039)*I22*$B$13)/($B$5*$B$11) -> 13.183666 | L22: =((G22/0.020885434273039)*J22*$B$13)/($B$5*$B$11) -> -6.5918329 | O22: =2*$B$5/($B$26*$B$27*$B$25*$B$13) -> 39.37849 | P22: =(0.88*O22)/(5.3+O22) -> 0.77560972 | S22: =1+($P$6*56*0.3048*D22*$B$26*$B$25*$B$13)/(2*$B$5*$B$11) -> 3.5937802 | T22: =1-($P$6*56*0.3048*D22*$B$26*$B$25*$B$13)/(2*$B$5*$B$11) -> -1.5937802 | U22: =1+($P$6*28*0.3048*D22*$B$26*$B$25*$B$13)/(2*$B$5*$B$11) -> 2.2968901 | V22: =1-($P$6*28*0.3048*D22*$B$26*$B$25*$B$13)/(2*$B$5*$B$11) -> -0.29689009
A23: β*AR/K | B23: =B20*B17/B22 -> 8.4 | D23: 170 | E23: =1.94384*D23 -> 330.4528 | F23: =E23/$B$9 -> 0.93694973 | G23: =(0.5*$B$26*D23^2)*0.020885434273039 -> 369.69829 | H23: 1 | I23: =H23*$B$10 -> 2.2 | J23: =$B$28*$H$6 -> -1.1 | K23: =((G23/0.020885434273039)*I23*$B$13)/($B$5*$B$11) -> 14.883123 | L23: =((G23/0.020885434273039)*J23*$B$13)/($B$5*$B$11) -> -7.4415614 | O23: =2*$B$5/($B$26*$B$27*$B$25*$B$13) -> 39.37849 | P23: =(0.88*O23)/(5.3+O23) -> 0.77560972 | S23: =1+($P$6*56*0.3048*D23*$B$26*$B$25*$B$13)/(2*$B$5*$B$11) -> 3.7558914 | T23: =1-($P$6*56*0.3048*D23*$B$26*$B$25*$B$13)/(2*$B$5*$B$11) -> -1.7558914 | U23: =1+($P$6*28*0.3048*D23*$B$26*$B$25*$B$13)/(2*$B$5*$B$11) -> 2.3779457 | V23: =1-($P$6*28*0.3048*D23*$B$26*$B$25*$B$13)/(2*$B$5*$B$11) -> -0.37794572
A24: cl alpha w (1/rad) tablas | B24: 4.7555497 | D24: 180 | E24: =1.94384*D24 -> 349.8912 | F24: =E24/$B$9 -> 0.99206442 | G24: =(0.5*$B$26*D24^2)*0.020885434273039 -> 414.47144 | H24: 1 | I24: =H24*$B$10 -> 2.2 | J24: =$B$28*$H$6 -> -1.1 | K24: =((G24/0.020885434273039)*I24*$B$13)/($B$5*$B$11) -> 16.685577 | L24: =((G24/0.020885434273039)*J24*$B$13)/($B$5*$B$11) -> -8.3427885 | O24: =2*$B$5/($B$26*$B$27*$B$25*$B$13) -> 39.37849 | P24: =(0.88*O24)/(5.3+O24) -> 0.77560972 | S24: =1+($P$6*56*0.3048*D24*$B$26*$B$25*$B$13)/(2*$B$5*$B$11) -> 3.9180027 | T24: =1-($P$6*56*0.3048*D24*$B$26*$B$25*$B$13)/(2*$B$5*$B$11) -> -1.9180027 | U24: =1+($P$6*28*0.3048*D24*$B$26*$B$25*$B$13)/(2*$B$5*$B$11) -> 2.4590013 | V24: =1-($P$6*28*0.3048*D24*$B$26*$B$25*$B$13)/(2*$B$5*$B$11) -> -0.45900135
A25: cl alpha aircraft (1/rad) at M=0 | B25: =1.1*B24 -> 5.2311047 | D25: 190 | E25: =1.94384*D25 -> 369.3296 | F25: =E25/$B$9 -> 1.0471791 | G25: =(0.5*$B$26*D25^2)*0.020885434273039 -> 461.80306 | H25: 1 | I25: =H25*$B$10 -> 2.2 | J25: =$B$28*$H$6 -> -1.1 | K25: =((G25/0.020885434273039)*I25*$B$13)/($B$5*$B$11) -> 18.591029 | L25: =((G25/0.020885434273039)*J25*$B$13)/($B$5*$B$11) -> -9.2955144 | O25: =2*$B$5/($B$26*$B$27*$B$25*$B$13) -> 39.37849 | P25: =(0.88*O25)/(5.3+O25) -> 0.77560972 | S25: =1+($P$6*56*0.3048*D25*$B$26*$B$25*$B$13)/(2*$B$5*$B$11) -> 4.080114 | T25: =1-($P$6*56*0.3048*D25*$B$26*$B$25*$B$13)/(2*$B$5*$B$11) -> -2.080114 | U25: =1+($P$6*28*0.3048*D25*$B$26*$B$25*$B$13)/(2*$B$5*$B$11) -> 2.540057 | V25: =1-($P$6*28*0.3048*D25*$B$26*$B$25*$B$13)/(2*$B$5*$B$11) -> -0.54005698
A26: Air density at h ft (kg/m^3) | B26: 1.225 | D26: 200 | E26: =1.94384*D26 -> 388.768 | F26: =E26/$B$9 -> 1.1022938 | G26: =(0.5*$B$26*D26^2)*0.020885434273039 -> 511.69314 | H26: 1 | I26: =H26*$B$10 -> 2.2 | J26: =$B$28*$H$6 -> -1.1 | K26: =((G26/0.020885434273039)*I26*$B$13)/($B$5*$B$11) -> 20.599478 | L26: =((G26/0.020885434273039)*J26*$B$13)/($B$5*$B$11) -> -10.299739 | O26: =2*$B$5/($B$26*$B$27*$B$25*$B$13) -> 39.37849 | P26: =(0.88*O26)/(5.3+O26) -> 0.77560972 | S26: =1+($P$6*56*0.3048*D26*$B$26*$B$25*$B$13)/(2*$B$5*$B$11) -> 4.2422252 | T26: =1-($P$6*56*0.3048*D26*$B$26*$B$25*$B$13)/(2*$B$5*$B$11) -> -2.2422252 | U26: =1+($P$6*28*0.3048*D26*$B$26*$B$25*$B$13)/(2*$B$5*$B$11) -> 2.6211126 | V26: =1-($P$6*28*0.3048*D26*$B$26*$B$25*$B$13)/(2*$B$5*$B$11) -> -0.62111261
A27: mean aerodynamic chord (c_bar) (m) | B27: 2.114 | D27: 210 | E27: =1.94384*D27 -> 408.2064 | F27: =E27/$B$9 -> 1.1574085 | G27: =(0.5*$B$26*D27^2)*0.020885434273039 -> 564.14169 | H27: 1 | I27: =H27*$B$10 -> 2.2 | J27: =$B$28*$H$6 -> -1.1 | K27: =((G27/0.020885434273039)*I27*$B$13)/($B$5*$B$11) -> 22.710924 | L27: =((G27/0.020885434273039)*J27*$B$13)/($B$5*$B$11) -> -11.355462 | O27: =2*$B$5/($B$26*$B$27*$B$25*$B$13) -> 39.37849 | P27: =(0.88*O27)/(5.3+O27) -> 0.77560972 | S27: =1+($P$6*56*0.3048*D27*$B$26*$B$25*$B$13)/(2*$B$5*$B$11) -> 4.4043365 | T27: =1-($P$6*56*0.3048*D27*$B$26*$B$25*$B$13)/(2*$B$5*$B$11) -> -2.4043365 | U27: =1+($P$6*28*0.3048*D27*$B$26*$B$25*$B$13)/(2*$B$5*$B$11) -> 2.7021682 | V27: =1-($P$6*28*0.3048*D27*$B$26*$B$25*$B$13)/(2*$B$5*$B$11) -> -0.70216824
A28: negative Cl max (-) M=0 | B28: -1.1 | D28: =0.514444*B7 -> 136.33913 | E28: =1.94384*D28 -> 265.02145 | F28: =E28/$B$9 -> 0.75142887 | G28: =(0.5*$B$26*D28^2)*0.020885434273039 -> 237.78837 | H28: 1 | I28: =H28*$B$10 -> 2.2 | J28: =$B$28*$H$6 -> -1.1 | K28: =((G28/0.020885434273039)*I28*$B$13)/($B$5*$B$11) -> 9.5727613 | L28: =((G28/0.020885434273039)*J28*$B$13)/($B$5*$B$11) -> -4.7863807 | O28: =2*$B$5/($B$26*$B$27*$B$25*$B$13) -> 39.37849 | P28: =(0.88*O28)/(5.3+O28) -> 0.77560972 | S28: =1+($P$6*56*0.3048*D28*$B$26*$B$25*$B$13)/(2*$B$5*$B$11) -> 3.2102108 | T28: =1-($P$6*56*0.3048*D28*$B$26*$B$25*$B$13)/(2*$B$5*$B$11) -> -1.2102108 | U28: =1+($P$6*28*0.3048*D28*$B$26*$B$25*$B$13)/(2*$B$5*$B$11) -> 2.1051054 | V28: =1-($P$6*28*0.3048*D28*$B$26*$B$25*$B$13)/(2*$B$5*$B$11) -> -0.10510538
D29: 283.5875 | E29: 551.25 | F29: =E29/$B$9 -> 1.5629873 | G29: =(0.5*$B$26*D29^2)*0.020885434273039 -> 1028.783 | H29: 2 | I29: =H29*$B$10 -> 4.4 | J29: =$B$28*$H$6 -> -1.1 | K29: =((G29/0.020885434273039)*I29*$B$13)/($B$5*$B$11) -> 82.832427 | L29: =((G29/0.020885434273039)*J29*$B$13)/($B$5*$B$11) -> -20.708107 | O29: =2*$B$5/($B$26*$B$27*$B$25*$B$13) -> 39.37849 | P29: =(0.88*O29)/(5.3+O29) -> 0.77560972 | U29: =1+($P$6*28*0.3048*D29*$B$26*$B$25*$B$13)/(2*$B$5*$B$11) -> 3.2986364 | V29: =1-($P$6*28*0.3048*D29*$B$26*$B$25*$B$13)/(2*$B$5*$B$11) -> -1.2986364
A30: Speeds | B30: n+ | D30: n- | G30: n+ | H30: n-
A31: V stall KEAS | B31: =SQRT((2*B5*B11)/(B26*B13*B10))*1.94384 -> 85.65691 | D31: =SQRT((2*B5*B11)/(B26*B13*-B28))*1.94384 -> 121.13716 | F31: V stall m/s | G31: =SQRT((2*B5*B11)/(B26*B13*2.2)) -> 44.065823 | H31: =SQRT((2*B5*B11)/(B26*B13*1.1)) -> 62.318485
A32: V flaps KEAS | B32: =1.944*G32 -> 79.882055 | F32: V stall flaps m/s | G32: =SQRT((2*B5*B11)/(B26*B13*2.2*1.15)) -> 41.091592
A33: V maneuver (V_A) KEAS | B33: =B31*SQRT(B15) -> 145.73597 | D33: =D31*SQRT(B16*-1) -> 121.13716
A34: V cruise KEAS | B34: =B7 -> 265.02229 | F34: V cruise m/s | G34: =B34/1.94384 -> 136.33956
A35: V NE | B35: =0.9*B36 -> 298.15007 | F35: VgE m/s | G35: 10.90344
A36: V dive KEAS | B36: =B8 -> 331.27786
A37: V_B KEAS | B37: =B31 * SQRT(1 + (P14 * G35 * G34 * B25 * B26 * B13) / (2 * B5 * B11)) -> 133.02694 | D37: =D31 * SQRT(1 + (P17 * G35 * G34 * B25 * B26 * B13) / (2 * B5 * B11)) -> 188.12851
A39: Loads
A40: n2 load factor | B40: =0.75*B15 -> 2.1710508
A41: proof load | B41: =1.25*B15 -> 3.618418
A42: Ultimate load | B42: =1.5*B15 -> 4.3421016
A45: Plot | B45: x | C45: y
...

Sheet Level Turn
B1: Unit | C1: Value | F1: w vs speed (KEAS)
A2: φ_max | B2: deg | C2: =ACOS(1/'V-n CL'!B15)*180/PI() -> 69.790437 | F2: Veq (KEAS) | G2: Veq (m/s) | H2: W (deg/s)
A3: ω_max | B3: deg/s | C3: =('V-n CL'!B11 * (SQRT('V-n SL'!B15^2 - 1)) / 'V-n SL'!G31) * (180 / PI()) -> 34.649983 | F3: ='V-n SL'!B31 -> 85.65691 | G3: =F3*0.514444 -> 44.065684 | H3: =(9.81* (SQRT('V-n SL'!$B$15^2 - 1)) /G3) * (180 / PI()) -> 34.650093
A4: R_min | B4: m | C4: ='V-n SL'!G31^2/(9.81*SQRT(2.89^2-1)) -> 73.001044 | F4: ='V-n SL'!E11 -> 85.657149 | G4: =F4*0.514444 -> 44.065807 | H4: =(9.81* (SQRT('V-n SL'!$B$15^2 - 1)) /G4) * (180 / PI()) -> 34.649996
A5: 360 turn time | B5: s | C5: =360/C3 -> 10.389616 | F5: ='V-n SL'!E12 -> 112.96804 | G5: =F5*0.514444 -> 58.115732 | H5: =(9.81* (SQRT('V-n SL'!$B$15^2 - 1)) /G5) * (180 / PI()) -> 26.273093
F6: ='V-n SL'!E13 -> 121.17674 | G6: =F6*0.514444 -> 62.338649 | H6: =(9.81* (SQRT('V-n SL'!$B$15^2 - 1)) /G6) * (180 / PI()) -> 24.493313
F7: ='V-n SL'!E14 -> 145.6181 | G7: =F7*0.514444 -> 74.912355 | H7: =(9.81* (SQRT('V-n SL'!$B$15^2 - 1)) /G7) * (180 / PI()) -> 20.382219
F19: R vs speed (KEAS)
F20: Veq (KEAS) | G20: Veq (m/s) | H20: R (m)
F21: 85.65691 | G21: =F21*0.514444 -> 44.065684 | H21: =G21^2/(9.81*SQRT(2.89^2-1)) -> 73.00058
F22: 97.192 | G22: =F22*0.514444 -> 49.999841 | H22: =G22^2/(9.81*SQRT(2.89^2-1)) -> 93.985865
F23: 116.6304 | G23: =F23*0.514444 -> 59.999809 | H23: =G23^2/(9.81*SQRT(2.89^2-1)) -> 135.33964
F24: 136.0688 | G24: =F24*0.514444 -> 69.999778 | H24: =G24^2/(9.81*SQRT(2.89^2-1)) -> 184.21229
F25: 166.47046 | G25: =F25*0.514444 -> 85.639728 | H25: =G25^2/(9.81*SQRT(2.89^2-1)) -> 275.72481
F31: Phi vs speed (KEAS)
F32: Veq (KEAS) | G32: n | H32: Phi (deg)
F33: 85.65691 | G33: 1 | H33: =ACOS(1/G33)*180/PI() -> 0
F34: 97.192 | G34: ='V-n SL'!K11 -> 1.0000056 | H34: =ACOS(1/G34)*180/PI() -> 0.19145896
F35: 116.6304 | G35: ='V-n SL'!K12 -> 1.7393477 | H35: =ACOS(1/G35)*180/PI() -> 54.905397
F36: 136.0688 | G36: ='V-n SL'!K13 -> 2.0013071 | H36: =ACOS(1/G36)*180/PI() -> 60.021604
F37: 166.47046 | G37: ='V-n SL'!K14 -> 2.8900535 | H37: =ACOS(1/G37)*180/PI() -> 69.756272
