Workbook

Sheet Hoja1
B2: Chord | C2: 0.7355 | D2: m
B3: Wingspan | C3: 3.2 | D3: m
B4: Lift slope | C4: 6.436 | D4: 1/rad
B5: aL=0 | C5: -4.1 | D5: deg | E5: =RADIANS(C5) -> -0.071558499 | F5: rad
B6: Moment coeffient | C6: -0.0981
B7: Drag coefficient | C7: 0.00524
B9: Density | C9: 1.225 | D9: kg/m3
B10: Visc din | C10: =1.79*10^-5 -> 1.79e-05 | D10: kg/m*s
B11: Mfus | C11: 19232.94 | D11: Nm
B12: Vinf | C12: 201 | D12: km/h | E12: =C12/3.6 -> 55.833333 | F12: m/s
B13: V2 | C13: 32 | D13: m/s
B14: Vrelative magnitud | C14: =SQRT((E12^2)+(C13^2)) -> 64.353408 | D14: m/s
B15: Theta Ang | C15: =DEGREES(ASIN(C13/C14)) -> 29.818503 | D15: deg
B16: q | C16: =(1/2)*C9*(C14)^2 -> 2536.5837 | D16: Pa
B17: D mass center-wing x | C17: 12.8 | D17: m
B18: D mass center-wing y | C18: 2.42 | D18: m
B19: D mass center-win magnitud | C19: =SQRT((C18^2)+(C17^2)) -> 13.026757 | D19: m
B21: Moment eq | C21: 0 = -Mfus + L*d + Mwing
B22: Mwing | C22: =(C16*(C2*C3)*C2*C6) -> -430.75818 | D22: Nm
B23: Lift wing | C23: =(-C11-C22)/C19 -> -1443.3509 | D23: N
B24: Cl | C24: =-C23/(C16*(C2*C3)) -> 0.24176314
B25: S | C25: =C2*C3 -> 2.3536 | D25: m2
B26: AR | C26: =(C3^2)/C25 -> 4.3507818
B27: e | C27: 0.97
B28: Lift Slope (With correction) | C28: =C4/(1+C4/(PI()*C26)) -> 4.3756486 | D28: 1/rad
B30: Assumption = Rectangular wing
B33: DATA LLT
B34: AoA | C34: -0.80192212 | D34: deg | E34: =RADIANS(C34) -> -0.013996181 | F34: rad | G34: PARA OBTENER ESTE VALOR DE AoA, SE DEFINIÓ UNO DE 0° PARA EMPEZAR, E HICE QUE EL EXCEL ITERARA HASTA OBTENER EL CL_W QUE NECESITABÁMOS (-0.252840)
B35: bw | C35: =C3 -> 3.2 | D35: m
B36: taper ratio | C36: 1
B37: Sw | C37: =C25 -> 2.3536 | D37: m2
B38: Btip | C38: 0
B39: Ageo | C39: 0
B40: Lift slope root | C40: =C4 -> 6.436
B41: Lift slope tip | C41: =C4 -> 6.436
B42: aL=0 root | C42: =C5 -> -4.1 | D42: deg | E42: =RADIANS(C42) -> -0.071558499
B43: aL=0 tip | C43: =C5 -> -4.1 | D43: deg | E43: =RADIANS(C43) -> -0.071558499
B44: AR | C44: =C26 -> 4.3507818
B45: C root | C45: =(2*C37)/(C35*(1+C36)) -> 0.7355 | D45: m
B46: C tip | C46: =C36*C45 -> 0.7355 | D46: m
...

Sheet Hoja2
B2: NACA | C2: 4415
B4: V | C4: 7 | D4: m/s
B5: Visc din | C5: =1.823*10^(-5) -> 1.823e-05 | D5: kg/(m*s)
B6: Density | C6: 1.201
B7: AoA | C7: 2.0426084 | D7: deg | E7: =RADIANS(C7) -> 0.035650243 | F7: rad
B8: bw | C8: 2.788 | D8: m
B9: c | C9: 0.465
B10: taper ratio | C10: 1
B11: Sw | C11: =C8*C9 -> 1.29642 | D11: m2
B12: Btip | C12: 0
B13: Ageo | C13: 0
B14: Lift slope root | C14: 5.541
B15: Lift slope tip | C15: 5.541
B16: aL=0 root | C16: -3.339 | D16: deg | E16: =RADIANS(C16) -> -0.058276544 | F16: rad
B17: aL=0 tip | C17: -3.339 | D17: deg | E17: =RADIANS(C17) -> -0.058276544 | F17: rad
B18: AR | C18: =(C8^2)/C11 -> 5.9956989
B19: C root | C19: =(2*C11)/(C8*(1+C10)) -> 0.465 | D19: m | E19: Peso Requerido | F19: 1.5 kg
B20: C tip | C20: =C10*C19 -> 0.465 | D20: m
B21: C av | C21: =(1/(2*C10))*C20*(1+C10) -> 0.465 | D21: m
B22: C mean | C22: =(2/3)*C19*((1+C10+C10^2)/(1+C10)) -> 0.465 | D22: m | F22: REAL Lift Slope | H22: =(G16-C59)/(E16-E7) -> 4.1069176
B23: Y | C23: =(C8/6)*((1+2*C10)/(1+C10)) -> 0.697 | D23: m
B24: Re | C24: =(C6*C4*C22)/C5 -> 214440.76
B25: h tip | C25: =C20*SIN(C12) -> 0
B26: q | C26: =(1/2)*C6*C4^2 -> 29.4245
B27: N | C27: 4
B29: k | C29: y(k) [m] | D29: Theta(k) [rad] | E29: C(k) | F29: a0(k) | G29: a L=0 (k) | H29: B(k) | I29: D(k)
B30: 1 | C30: =-($C$8/2)*(1-(2*B30-1)/(2*$C$27)) -> -1.21975 | D30: =ACOS(-(2*C30)/$C$8) -> 0.50536051 | E30: =$C$19*(1-2*(($C$10-1)/$C$8)*C30) -> 0.465 | F30: =$C$14-2*(($C$15-$C$14)/$C$8)*C30 -> 5.541 | G30: =$E$16-2*(($E$17-$E$16)/$C$8)*C30 -> -0.058276544 | H30: 0 | I30: =$E$7-G30+H30 -> 0.093926786
B31: 2 | C31: =-($C$8/2)*(1-(2*B31-1)/(2*$C$27)) -> -0.87125 | D31: =ACOS(-(2*C31)/$C$8) -> 0.89566479 | E31: =$C$19*(1-2*(($C$10-1)/$C$8)*C31) -> 0.465 | F31: =$C$14-2*(($C$15-$C$14)/$C$8)*C31 -> 5.541 | G31: =$E$16-2*(($E$17-$E$16)/$C$8)*C31 -> -0.058276544 | H31: 0 | I31: =$E$7-G31+H31 -> 0.093926786
B32: 3 | C32: =-($C$8/2)*(1-(2*B32-1)/(2*$C$27)) -> -0.52275 | D32: =ACOS(-(2*C32)/$C$8) -> 1.1863996 | E32: =$C$19*(1-2*(($C$10-1)/$C$8)*C32) -> 0.465 | F32: =$C$14-2*(($C$15-$C$14)/$C$8)*C32 -> 5.541 | G32: =$E$16-2*(($E$17-$E$16)/$C$8)*C32 -> -0.058276544 | H32: 0 | I32: =$E$7-G32+H32 -> 0.093926786
B33: 4 | C33: =-($C$8/2)*(1-(2*B33-1)/(2*$C$27)) -> -0.17425 | D33: =ACOS(-(2*C33)/$C$8) -> 1.4454685 | E33: =$C$19*(1-2*(($C$10-1)/$C$8)*C33) -> 0.465 | F33: =$C$14-2*(($C$15-$C$14)/$C$8)*C33 -> 5.541 | G33: =$E$16-2*(($E$17-$E$16)/$C$8)*C33 -> -0.058276544 | H33: 0 | I33: =$E$7-G33+H33 -> 0.093926786
B35: C
C36: n
B37: k | C37: 1 | D37: 2 | E37: 3 | F37: 4
B38: 1 | C38: =((((4*$C$8)/($F30*$E30))+(2*C$37-1)/(SIN($D30)))*SIN((2*C$37-1)*$D30)) -> 3.0954017 | D38: =((((4*$C$8)/($F30*$E30))+(2*D$37-1)/(SIN($D30)))*SIN((2*D$37-1)*$D30)) -> 10.509266 | E38: =((((4*$C$8)/($F30*$E30))+(2*E$37-1)/(SIN($D30)))*SIN((2*E$37-1)*$D30)) -> 8.453506 | F38: =((((4*$C$8)/($F30*$E30))+(2*F$37-1)/(SIN($D30)))*SIN((2*F$37-1)*$D30)) -> -7.2456777
B39: 2 | C39: =((((4*$C$8)/($F31*$E31))+(2*C$37-1)/(SIN($D31)))*SIN((2*C$37-1)*$D31)) -> 4.3787338 | D39: =((((4*$C$8)/($F31*$E31))+(2*D$37-1)/(SIN($D31)))*SIN((2*D$37-1)*$D31)) -> 3.5880378 | E39: =((((4*$C$8)/($F31*$E31))+(2*E$37-1)/(SIN($D31)))*SIN((2*E$37-1)*$D31)) -> -10.440688 | F39: =((((4*$C$8)/($F31*$E31))+(2*F$37-1)/(SIN($D31)))*SIN((2*F$37-1)*$D31)) -> -0.17990481
B40: 3 | C40: =((((4*$C$8)/($F32*$E32))+(2*C$37-1)/(SIN($D32)))*SIN((2*C$37-1)*$D32)) -> 5.0123889 | D40: =((((4*$C$8)/($F32*$E32))+(2*D$37-1)/(SIN($D32)))*SIN((2*D$37-1)*$D32)) -> -3.0679201 | E40: =((((4*$C$8)/($F32*$E32))+(2*E$37-1)/(SIN($D32)))*SIN((2*E$37-1)*$D32)) -> -3.3444412 | F40: =((((4*$C$8)/($F32*$E32))+(2*F$37-1)/(SIN($D32)))*SIN((2*F$37-1)*$D32)) -> 10.692449
B41: 4 | C41: =((((4*$C$8)/($F33*$E33))+(2*C$37-1)/(SIN($D33)))*SIN((2*C$37-1)*$D33)) -> 5.2942957 | D41: =((((4*$C$8)/($F33*$E33))+(2*D$37-1)/(SIN($D33)))*SIN((2*D$37-1)*$D33)) -> -6.8384022 | E41: =((((4*$C$8)/($F33*$E33))+(2*E$37-1)/(SIN($D33)))*SIN((2*E$37-1)*$D33)) -> 7.5879211 | F41: =((((4*$C$8)/($F33*$E33))+(2*F$37-1)/(SIN($D33)))*SIN((2*F$37-1)*$D33)) -> -7.2767691
B44: C^-1
C45: n
B46: k | C46: 1 | D46: 2 | E46: 3 | F46: 4
...

Sheet Hoja3
A1: Alpha | B1: CL_w | C1: L [N] | D1: L [kg]
A2: -12 | B2: -0.62081385 | C2: =Hoja2!$C$26*Hoja2!$E$96*Hoja2!$C$8*Hoja3!B2 -> -23.681882 | D2: =C2/9.81 -> -2.4140552
A3: -11 | B3: -0.54913461 | C3: =Hoja2!$C$26*Hoja2!$E$96*Hoja2!$C$8*Hoja3!B3 -> -20.947569 | D3: =C3/9.81 -> -2.1353282
A4: -10 | B4: -0.47745538 | C4: =Hoja2!$C$26*Hoja2!$E$96*Hoja2!$C$8*Hoja3!B4 -> -18.213257 | D4: =C4/9.81 -> -1.8566011
A5: -9 | B5: -0.40577614 | C5: =Hoja2!$C$26*Hoja2!$E$96*Hoja2!$C$8*Hoja3!B5 -> -15.478944 | D5: =C5/9.81 -> -1.577874
A6: -8 | B6: -0.33409691 | C6: =Hoja2!$C$26*Hoja2!$E$96*Hoja2!$C$8*Hoja3!B6 -> -12.744631 | D6: =C6/9.81 -> -1.2991469
A7: -7 | B7: -0.26241768 | C7: =Hoja2!$C$26*Hoja2!$E$96*Hoja2!$C$8*Hoja3!B7 -> -10.010319 | D7: =C7/9.81 -> -1.0204198
A8: -6 | B8: -0.19073844 | C8: =Hoja2!$C$26*Hoja2!$E$96*Hoja2!$C$8*Hoja3!B8 -> -7.2760059 | D8: =C8/9.81 -> -0.74169276
A9: -5 | B9: -0.11905921 | C9: =Hoja2!$C$26*Hoja2!$E$96*Hoja2!$C$8*Hoja3!B9 -> -4.5416933 | D9: =C9/9.81 -> -0.46296568
A10: -4 | B10: -0.047379974 | C10: =Hoja2!$C$26*Hoja2!$E$96*Hoja2!$C$8*Hoja3!B10 -> -1.8073807 | D10: =C10/9.81 -> -0.1842386
A11: -3 | B11: 0.02429926 | C11: =Hoja2!$C$26*Hoja2!$E$96*Hoja2!$C$8*Hoja3!B11 -> 0.92693199 | D11: =C11/9.81 -> 0.09448848
A12: -2 | B12: 0.095978495 | C12: =Hoja2!$C$26*Hoja2!$E$96*Hoja2!$C$8*Hoja3!B12 -> 3.6612446 | D12: =C12/9.81 -> 0.37321556
A13: -1 | B13: 0.16765773 | C13: =Hoja2!$C$26*Hoja2!$E$96*Hoja2!$C$8*Hoja3!B13 -> 6.3955573 | D13: =C13/9.81 -> 0.65194264
... A26: 12 | B26: 1.0994878 | C26: =Hoja2!$C$26*Hoja2!$E$96*Hoja2!$C$8*Hoja3!B26 -> 41.941622 | D26: =C26/9.81 -> 4.2753947
A30: L = 1.5Kg | B30: 2.0426084
A35: AR 6 | H35: AR 3 | O35: AR 10
A36: Points of control | B36: y [m] | C36: y/(bw/2) | D36: CL_w(y) | E36: L(y) [N] | H36: Points of control | I36: y [m] | J36: y/(bw/2) | K36: CL_w(y) | L36: L(y) [N] | O36: Points of control | P36: y [m] | Q36: y/(bw/2) | R36: CL_w(y) | S36: L(y) [N]
A37: 0 | B37: 1.394 | C37: 1 | D37: 0 | E37: 0 | H37: 0 | I37: 1 | J37: 1 | K37: 0 | L37: 0 | O37: 0 | P37: 2 | Q37: 1 | R37: 0 | S37: 0
A38: 1 | B38: 1.21975 | C38: 0.875 | D38: 0.77607157 | E38: 10.618516 | H38: 1 | I38: 0.875 | J38: 0.875 | K38: 0.72292113 | L38: 13.826535 | O38: 1 | P38: 1.75 | Q38: 0.875 | R38: 0.8191839 | S38: 9.6416307
A39: 2 | B39: 0.87125 | C39: 0.625 | D39: 1.0641374 | E39: 14.559946 | H39: 2 | I39: 0.625 | J39: 0.625 | K39: 1.040764 | L39: 19.905575 | O39: 2 | P39: 1.25 | Q39: 0.625 | R39: 1.0830965 | S39: 12.747829
A40: 3 | B40: 0.52275 | C40: 0.375 | D40: 1.1154709 | E40: 15.26231 | H40: 3 | I40: 0.375 | J40: 0.375 | K40: 1.1370596 | L40: 21.747316 | O40: 3 | P40: 0.75 | Q40: 0.375 | R40: 1.0979594 | S40: 12.922763
A41: 4 | B41: 0.17425 | C41: 0.125 | D41: 1.1145167 | E41: 15.249255 | H41: 4 | I41: 0.125 | J41: 0.125 | K41: 1.1640285 | L41: 22.263123 | O41: 4 | P41: 0.25 | Q41: 0.125 | R41: 1.0743558 | S41: 12.644953
A42: 5 | B42: 0 | C42: 0 | D42: 1.1133331 | E42: 15.233061 | H42: 5 | I42: 0 | J42: 0 | K42: 1.1665632 | L42: 22.311601 | O42: 5 | P42: 0 | Q42: 0 | R42: 1.0701562 | S42: 12.595524
C47: AR 3 | D47: AR 6 | E47: AR 10
B48: Alpha | C48: CL_w | D48: CL_w | E48: CL_w
B49: -12 | C49: -0.5115957 | D49: -0.62081385 | E49: -0.68425739
B50: 0 | C50: 0.19723104 | D50: 0.23933696 | E50: 0.2637958
B51: 12 | C51: 0.90605778 | D51: 1.0994878 | E51: 1.211849
A70: e | B70: 0.96785791
A72: Alpha | B72: Cd_profile | C72: Cl_Profile | D72: AR | E72: Cdi | F72: CD_w
A73: -6 | B73: 0.03476 | C73: -0.19073844 | D73: =Hoja2!$C$18 -> 5.9956989 | E73: =(C73^2)/(PI()*$B$70*D73) -> 0.0019956077 | F73: =E73+B73 -> 0.036755608
A74: -3 | B74: 0.02369 | C74: 0.02429926 | D74: =Hoja2!$C$18 -> 5.9956989 | E74: =(C74^2)/(PI()*$B$70*D74) -> 3.2388051e-05 | F74: =E74+B74 -> 0.023722388
A75: 0 | B75: 0.01724 | C75: 0.23933696 | D75: =Hoja2!$C$18 -> 5.9956989 | E75: =(C75^2)/(PI()*$B$70*D75) -> 0.0031420874 | F75: =E75+B75 -> 0.020382087
A76: 3 | B76: 0.01918 | C76: 0.45437467 | D76: =Hoja2!$C$18 -> 5.9956989 | E76: =(C76^2)/(PI()*$B$70*D76) -> 0.011324706 | F76: =E76+B76 -> 0.030504706
A77: 6 | B77: 0.02311 | C77: 0.66941237 | D77: =Hoja2!$C$18 -> 5.9956989 | E77: =(C77^2)/(PI()*$B$70*D77) -> 0.024580243 | F77: =E77+B77 -> 0.047690243
A78: 9 | B78: 0.02696 | C78: 0.88445007 | D78: =Hoja2!$C$18 -> 5.9956989 | E78: =(C78^2)/(PI()*$B$70*D78) -> 0.042908699 | F78: =E78+B78 -> 0.069868699
A79: 12 | B79: 0.0331 | C79: 1.0994878 | D79: =Hoja2!$C$18 -> 5.9956989 | E79: =(C79^2)/(PI()*$B$70*D79) -> 0.066310075 | F79: =E79+B79 -> 0.099410075
